<?xml version="1.0"?>
<robot name="hehe">
  <link name="base_link">
   <visual>
    <geometry>
      <box size="0.6 0.4 0.2"/>
    </geometry>
    <material name="blue">
      <color rgba="0.0 0.0 1.0 1.0"/>
    </material>
    <origin xyz="0 0 0.1" rpy="0 0 0"/>
   </visual>
  </link>
  
  <joint name="right_back_joint" type="continuous">
     <parent link="base_link"/>
     <child link="right_back_link"/>
     <origin xyz="0.2 0.215 0" rpy="0 0 0"/>
     <axis xyz = "0 1 0"/>     
  </joint>

  <link name="right_back_link">
    <visual>
     <geometry>
       <cylinder radius="0.1" length="0.04"/>
     </geometry>
     <material name="white">
       <color rgba="1.0 1.0 1.0 1.0"/>
     </material>
     <origin xyz="0 0 0" rpy="${pi/2} 0 0"/>
    </visual>
  </link>
  
  <joint name="left_back_joint" type="continuous">
     <parent link="base_link"/>
     <child link="left_back_link"/>
     <origin xyz="0.2 -0.215 0" rpy="0 0 0"/> 
     <axis xyz = "0 1 0"/>      
  </joint>

  <link name="left_back_link">
    <visual>
     <geometry>
       <cylinder radius="0.1" length="0.04"/>
     </geometry>
     <material name="white">
       <color rgba="1.0 1.0 1.0 1.0"/>
     </material>
     <origin xyz="0 0 0" rpy="${pi/2} 0 0"/>
    </visual>
  </link>
  
  <joint name="caster_wheel" type="fixed">
     <parent link="base_link"/>
     <child link="caster_wheel_link"/>
     <origin xyz="-0.2 0 -0.025" rpy="0 0 0"/>       
  </joint>
  
  <link name="caster_wheel_link">
    <visual>
     <geometry>
       <sphere radius="0.05"/>
     </geometry>
     <material name="white">
       <color rgba="1.0 1.0 1.0 1.0"/>
     </material>
     <origin xyz="0 0 0" rpy="0 0 0"/>
    </visual>
  </link>

  <joint name="shoulder_joint" type="revolute">
     <parent link="base_link"/>
     <child link="cylinder"/>
     <origin xyz="-0.2 0 0.2" rpy="0 0 0"/>
     <axis xyz= "0 0 1"/>
     <limit lower="-0.5" upper="0.5" velocity="10" effort="10"/>
  </joint>


  <link name="cylinder">
    <visual>
     <geometry>
       <cylinder radius="0.05" length="0.2"/>
     </geometry>
     <material name="white">
       <color rgba="1.0 1.0 1.0 1.0"/>
     </material>
     <origin xyz="0 0 0.1" rpy="0 0 0"/>
    </visual>
  </link>
  
  <joint name="elbow_sp" type="revolute">
     <parent link="cylinder"/>
     <child link="elbow_sp"/>
     <origin xyz="0 0 0.225" rpy="0 0 0"/> 
     <axis xyz= "0 1 0"/>
     <limit lower="-0.5" upper="0.5" velocity="10" effort="10"/>      
  </joint>
  
  <link name="elbow_sp">
    <visual>
     <geometry>
       <sphere radius="0.05"/>
     </geometry>
     <material name="white">
       <color rgba="1.0 1.0 1.0 1.0"/>
     </material>
     <origin xyz="0 0 0" rpy="0 0 0"/>
    </visual>
  </link>
  
  <joint name="elbow_joint" type="revolute">
     <parent link="elbow_sp"/>
     <child link="elbow"/>
     <origin xyz="-0.1 0 0.1" rpy="0 -${pi/4} 0"/>
     <axis xyz= "0 0 1"/>
     <limit lower="-0.5" upper="0.5" velocity="10" effort="10"/>
  </joint>


  <link name="elbow">
    <visual>
     <geometry>
       <cylinder radius="0.05" length="0.2"/>
     </geometry>
     <material name="white">
       <color rgba="1.0 1.0 1.0 1.0"/>
     </material>
     <origin xyz="0 0 0" rpy="0 0 0"/>
    </visual>
  </link>
  
  <joint name="wrist_sp" type="revolute">
     <parent link="elbow"/>
     <child link="wrist_sp"/>
     <origin xyz="0 0 0.15" rpy="0 0 0"/> 
     <axis xyz= "0 1 0"/>
     <limit lower="-0.5" upper="0.5" velocity="10" effort="10"/>      
  </joint>
  
  <link name="wrist_sp">
    <visual>
     <geometry>
       <sphere radius="0.05"/>
     </geometry>
     <material name="white">
       <color rgba="1.0 1.0 1.0 1.0"/>
     </material>
     <origin xyz="0 0 0" rpy="0 0 0"/>
    </visual>
  </link>
  
  <joint name="palm_joint" type="revolute">
     <parent link="wrist_sp"/>
     <child link="palm"/>
     <origin xyz="-0.1 0 0.08" rpy="0 -${pi/4} 0"/>
     <axis xyz= "0 0 1"/>
     <limit lower="-0.5" upper="0.5" velocity="10" effort="10"/>
  </joint> 

  <link name="palm">
    <visual>
     <geometry>
       <box size="0.1 0.1 0.15"/>
     </geometry>
     <material name="white">
       <color rgba="0.0 1.0 0.0 1.0"/>
     </material>
     <origin xyz="0 0 0" rpy="0 0 0"/>
    </visual>
  </link>


  <joint name="left_grip" type="prismatic">
     <parent link="palm"/>
     <child link="left_grip"/>
     <origin xyz="0 0.02 0.1" rpy="0 0 0"/>
     <axis xyz= "0 1 0"/>
     <limit lower="-0.02" upper="0.02" velocity="10" effort="10"/>
  </joint> 

  <link name="left_grip">
    <visual>
     <geometry>
       <box size="0.1 0.02 0.1"/>
     </geometry>
     <material name="white">
       <color rgba="0.0 1.0 0.0 1.0"/>
     </material>
     <origin xyz="0 0 0" rpy="0 0 0"/>
    </visual>
  </link>
  
  <joint name="right_grip" type="prismatic">
     <parent link="palm"/>
     <child link="right_grip"/>
     <origin xyz="0 -0.02 0.1" rpy="0 0 0"/>
     <axis xyz= "0 1 0"/>
     <limit lower="-0.02" upper="0.02" velocity="10" effort="10"/>
  </joint> 

  <link name="right_grip">
    <visual>
     <geometry>
       <box size="0.1 0.02 0.1"/>
     </geometry>
     <material name="white">
       <color rgba="0.0 1.0 0.0 1.0"/>
     </material>
     <origin xyz="0 0 0" rpy="0 0 0"/>
    </visual>
  </link>
</robot>
